Workbook

Sheet 최종 스펙 요약
A1: 최종 확정 스펙 (4차 크로스체크 반영, v4 — 9단계 구조) | 브랜드명: Host ON (AI)
A3: 구분 | B3: 최종 결정 | C3: 비고
A4: 데이터 계층 | B4: Host → Property(단일 accommodation_type ENUM) → Room → Bed (모두 optional) | C4: 법적으로 한 공간 복수유형 등록 불가
A5: 예약 단위 | B5: Reservation.bookable_unit_type(PROPERTY/ROOM/BED) | C5: 본인숙소=PROPERTY단위, 호스텔=ROOM단위
A6: 예약/환불/정산 상태 | B6: reservation_status / refund_status / financial_status(ESTIMATED/CONFIRMED/MANUALLY_ADJUSTED) 모두 분리
A7: 채널 수수료 | B7: commission_rate 0.155(2026.5.25 한국 단일수수료 전환 반영)
A8: 네이버예약 | B8: iCal 미제공, 내보내기 전용으로만 UI 표기
A9: 숙박업 유형 법정명칭 | B9: '외국인관광 도시민박업' 정확 표기
A10: 등록증 갱신방식 | B10: 정기갱신 없음, 변경사유 발생시 D+30 신고(EVENT_BASED)
A11: iCal 표현 | B11: '실시간' 제거 → '동기화 시점 중복예약 충돌 감지'
A12: Mock/Real 경계 | B12: iCal=Real, AI응답=Real(LLM), 스마트락/가격반영/OTA메시징=Mock | C12: 화면에 '시뮬레이션' 뱃지로 명시 (신규)
A13: DB 전략(신규 확정) | B13: 로컬 개발부터 Docker Postgres 사용(MariaDB 대신 채택) | C13: MariaDB↔PostgreSQL 이원화로 인한 배포당일 문법오류 리스크 원천차단
A14: 배포 전략(신규 확정) | B14: Render 무료플랜 750시간 한도 보존을 위해 스테이징=프로덕션 서비스를 10/1에 생성, 10/8에 그대로 정식승격(재생성 아님) | C14: 배포를 마지막에 몰아넣지 않되, 너무 일찍 만들어 무료시간을 낭비하지도 않음
A15: UI/UX 설계(신규 확정) | B15: 1단계와 2단계 사이 1.5단계로 독립 — 화면목록/와이어프레임/디자인시스템/로그인화면 설계 | C15: 로직은 촘촘했으나 화면 설계 단계 자체가 누락되어 있었음
A16: 회원가입/로그인(신규 확정) | B16: 기능명세에는 있었으나 체크리스트에서 누락됐던 항목, 1.5단계 설계+2단계 구현으로 명시 추가
A17: 통합QA·보안(신규 확정) | B17: 5.5단계로 독립 — 회귀테스트, 예외케이스 전수점검, 보안점검, Mock라벨 전수확인, README | C17: QA를 마지막에 몰아넣지 않고 별도 단계화
A18: 데모 데이터(신규 확정) | B18: 골든패스 시드 스크립트(호스트1+숙소3+예약15~20건+긴급알림 시나리오) 사전 제작, 발표전 재실행 | C18: 발표 중 빈화면/알림 미표시 방지
A19: 최종 데모검증(신규 확정) | B19: 6.5단계 — Demo Reset+E2E 시나리오 리허설+예상 Q&A 준비, 10/11에 배치 | C19: 10/12는 발표당일이라 작업 없음
A20: 발표 방식 | B20: 음성 나레이션 포함 영상으로 발표, 제출자료 자체가 영상일 필요는 없음 | C20: 제출마감 10/10, 10/11은 6.5단계 최종검증, 10/12 발표
A21: 작업 리듬 | B21: 주간(9~18시)=본인 직접개발·실행 / 야간=AI와 문서·콘텐츠 초안 / 익일아침=검토·보완 | C21: 체크리스트 '담당' 열에 표시
A22: 연장근무일(확정, 9/4 재조정) | B22: 주중 월/수/금 저녁 3시간 반복 추가근무(9/24~25 명절휴무 제외) | C22: 고정 4일 방식→매주 반복 패턴으로 변경, 10/5~10/11 최고부하구간은 월수금이 자연스럽게 커버
A23: 위험1 재점검(반영) | B23: 예약→AI대화→ActionCenter 통합 딥링크 부재 → 신규 태스크 추가(9/26) | C23: 화면이 따로 노는 'API조합툴'처럼 보이는 것 방지
A24: 위험2 재점검(기확인) | B24: AI텍스트 마크다운 렌더링, 에러 Toast 처리는 이미 반영돼 있었음(9/20,9/23) | C24: 추가조치 불필요
A25: 외부 제출마감(신규확정) | B25: 9/3(목) 11:00 기획서 제출(주제/선정이유/일정표/기술스택 필수포함) / 10/10 설명문서+소스코드 제출 | C25: 9/3은 개발 착수 초반이라 기존 대화내용(스펙/일정/스택)을 취합하는 수준으로 대응
A26: 인프라 제공현황(신규확인) | B26: Azure Cloud(확인 완료, 전환 안함) / Gemini Advanced(개인 구독, API 아님) / Google AI Studio 무료 API키(백업용 확보, Claude 유지) / HuggingFace 조직(무료 로컬 임베딩과 부합) | C26: LLM=Claude API 유지, 배포=Azure 전환 없이 Render 그대로 확정
A27: 배포 최종확정 | B27: Vercel(프론트)+Render(백엔드, Hobby 무료플랜)+Supabase(DB) 그대로 확정 | C27: Render 무료: 월750시간/워크스페이스, DB는 Supabase 사용하므로 Render의 '무료DB 30일만료' 함정 해당없음. 스테이징=프로덕션 서비스 통합(10/1생성→10/8 그대로 승격)으로 750시간 한도 내 안전
A28: AI 아키텍처 확정(비용통제) | B28: RAG검색(로컬벡터, LLM비용0)→Claude 1회 통합호출(분류+위험도+다국어+근거 동시반환), 멀티스텝 분리 금지 | C28: 1문의=정상1회, 실패시 최대2회 재시도(최대3회/문의). retry×step 곱연산 폭주 방지가 핵심
... A30: 예상 비용(참고치) | B30: 개발~데모 전체 약 $15~$100 범위(추정치, 실측 필요) — 프로젝트를 무너뜨릴 수준 아님 | C30: 실제 개발착수 후 50~100건 실측하여 재계산 권장. Claude Pro/Google AI Pro 구독은 API비용과 별개(개발도구용)
A32: Action Center 규칙표
A33: 분류 | B33: 트리거 조건 | C33: 성격
A34: 🔴 지금 처리 필요 | B34: iCal 동기화 시점 중복예약 충돌 감지 / 고위험 승인대기 / 체크인 2시간전 청소 미완료 | C34: 시스템 즉각 개입
A35: 🟡 오늘 확인 | B35: EVENT_BASED 신고 D-30 / 청소 비품부족 플래그 / 신규예약 정산검토 대기 | C35: 당일 업무 큐
A36: 🟢 자동 처리 | B36: 저위험 자동응답 발송완료 / 청소완료+비번전송 완료 | C36: 사후 모니터링

Sheet 진행현황 요약
A1: 3rd Host AI — 진행현황 요약 (9단계 구조, 8/31 개발착수 → 10/10 완료)
A3: 카테고리 | B3: 일정(시작~종료) | C3: 전체 | D3: 완료 | E3: 진행중 | F3: 완료율
A4: 데이터모델 설계(P0) | B4: 2026-08-31 ~ 2026-09-04 | C4: =COUNTIF(체크리스트!$B$4:$B$400,A4) | D4: =COUNTIFS(체크리스트!$B$4:$B$400,A4,체크리스트!$E$4:$E$400,"완료") | E4: =COUNTIFS(체크리스트!$B$4:$B$400,A4,체크리스트!$E$4:$E$400,"진행중") | F4: =IFERROR(D4/C4,0)
A5: UI/UX 설계 | B5: 2026-09-07 ~ 2026-09-09 | C5: =COUNTIF(체크리스트!$B$4:$B$400,A5) | D5: =COUNTIFS(체크리스트!$B$4:$B$400,A5,체크리스트!$E$4:$E$400,"완료") | E5: =COUNTIFS(체크리스트!$B$4:$B$400,A5,체크리스트!$E$4:$E$400,"진행중") | F5: =IFERROR(D5/C5,0)
A6: 기반 인프라 | B6: 2026-09-05 ~ 2026-09-18 | C6: =COUNTIF(체크리스트!$B$4:$B$400,A6) | D6: =COUNTIFS(체크리스트!$B$4:$B$400,A6,체크리스트!$E$4:$E$400,"완료") | E6: =COUNTIFS(체크리스트!$B$4:$B$400,A6,체크리스트!$E$4:$E$400,"진행중") | F6: =IFERROR(D6/C6,0)
A7: 고객 응대 자동화 | B7: 2026-09-17 ~ 2026-09-28 | C7: =COUNTIF(체크리스트!$B$4:$B$400,A7) | D7: =COUNTIFS(체크리스트!$B$4:$B$400,A7,체크리스트!$E$4:$E$400,"완료") | E7: =COUNTIFS(체크리스트!$B$4:$B$400,A7,체크리스트!$E$4:$E$400,"진행중") | F7: =IFERROR(D7/C7,0)
A8: 비대면 체크인 | B8: 2026-09-29 ~ 2026-09-30 | C8: =COUNTIF(체크리스트!$B$4:$B$400,A8) | D8: =COUNTIFS(체크리스트!$B$4:$B$400,A8,체크리스트!$E$4:$E$400,"완료") | E8: =COUNTIFS(체크리스트!$B$4:$B$400,A8,체크리스트!$E$4:$E$400,"진행중") | F8: =IFERROR(D8/C8,0)
A9: 청소·시설 관리 | B9: 2026-09-28 ~ 2026-10-03 | C9: =COUNTIF(체크리스트!$B$4:$B$400,A9) | D9: =COUNTIFS(체크리스트!$B$4:$B$400,A9,체크리스트!$E$4:$E$400,"완료") | E9: =COUNTIFS(체크리스트!$B$4:$B$400,A9,체크리스트!$E$4:$E$400,"진행중") | F9: =IFERROR(D9/C9,0)
A10: 정산 리포트 | B10: 2026-10-02 ~ 2026-10-06 | C10: =COUNTIF(체크리스트!$B$4:$B$400,A10) | D10: =COUNTIFS(체크리스트!$B$4:$B$400,A10,체크리스트!$E$4:$E$400,"완료") | E10: =COUNTIFS(체크리스트!$B$4:$B$400,A10,체크리스트!$E$4:$E$400,"진행중") | F10: =IFERROR(D10/C10,0)
A11: 동적 가격 책정 | B11: 2026-10-05 ~ 2026-10-07 | C11: =COUNTIF(체크리스트!$B$4:$B$400,A11) | D11: =COUNTIFS(체크리스트!$B$4:$B$400,A11,체크리스트!$E$4:$E$400,"완료") | E11: =COUNTIFS(체크리스트!$B$4:$B$400,A11,체크리스트!$E$4:$E$400,"진행중") | F11: =IFERROR(D11/C11,0)
A12: 알림·액션센터 | B12: 2026-10-06 ~ 2026-10-06 | C12: =COUNTIF(체크리스트!$B$4:$B$400,A12) | D12: =COUNTIFS(체크리스트!$B$4:$B$400,A12,체크리스트!$E$4:$E$400,"완료") | E12: =COUNTIFS(체크리스트!$B$4:$B$400,A12,체크리스트!$E$4:$E$400,"진행중") | F12: =IFERROR(D12/C12,0)
A13: 컴플라이언스 | B13: 2026-10-01 ~ 2026-10-07 | C13: =COUNTIF(체크리스트!$B$4:$B$400,A13) | D13: =COUNTIFS(체크리스트!$B$4:$B$400,A13,체크리스트!$E$4:$E$400,"완료") | E13: =COUNTIFS(체크리스트!$B$4:$B$400,A13,체크리스트!$E$4:$E$400,"진행중") | F13: =IFERROR(D13/C13,0)
A14: 통합QA·보안 | B14: 2026-10-08 ~ 2026-10-09 | C14: =COUNTIF(체크리스트!$B$4:$B$400,A14) | D14: =COUNTIFS(체크리스트!$B$4:$B$400,A14,체크리스트!$E$4:$E$400,"완료") | E14: =COUNTIFS(체크리스트!$B$4:$B$400,A14,체크리스트!$E$4:$E$400,"진행중") | F14: =IFERROR(D14/C14,0)
A15: 마무리 | B15: 2026-09-05 ~ 2026-10-10 | C15: =COUNTIF(체크리스트!$B$4:$B$400,A15) | D15: =COUNTIFS(체크리스트!$B$4:$B$400,A15,체크리스트!$E$4:$E$400,"완료") | E15: =COUNTIFS(체크리스트!$B$4:$B$400,A15,체크리스트!$E$4:$E$400,"진행중") | F15: =IFERROR(D15/C15,0)
A16: 최종 데모검증 | B16: 2026-10-11 ~ 2026-10-11 | C16: =COUNTIF(체크리스트!$B$4:$B$400,A16) | D16: =COUNTIFS(체크리스트!$B$4:$B$400,A16,체크리스트!$E$4:$E$400,"완료") | E16: =COUNTIFS(체크리스트!$B$4:$B$400,A16,체크리스트!$E$4:$E$400,"진행중") | F16: =IFERROR(D16/C16,0)
A18: 전체 합계 | B18: 2026-08-31 ~ 2026-10-11 | C18: =SUM(C4:C16) | D18: =SUM(D4:D16) | E18: =SUM(E4:E16) | F18: =IFERROR(D18/C18,0)
A20: 개발 착수일 | B20: 2026-08-31(월)
A21: 제출 마감일 | B21: 2026-10-10
A22: 오늘 날짜 | B22: =TODAY()
A23: D-day(제출까지) | B23: =DATE(2026,10,10)-TODAY()
A25: ★ 실제 진행률 (일일 크로스체크 ☑ 기준)
A26: 완료 개수 | B26: =COUNTIF('일일 크로스체크'!G:G,"☑")
A27: 전체 개수 | B27: =COUNTIF('일일 크로스체크'!G:G,"☑")+COUNTIF('일일 크로스체크'!G:G,"☐")
A28: 실제 완료율 | B28: =IFERROR(B26/B27,0)
A29: ⚠ 참고: 위 카테고리별 표(완료/진행중 열)는 '체크리스트' 시트의 상태값을 세는 것이라 별개입니다. 매일 체크하시는 '일일 크로스체크'만 쓰신다면 이 박스가 실제 진행률입니다.
A31: 완료 | B31: 진행중 | C31: 예정
A32: ※ 노랑=차별화 / 빨강=P0 / 보라=검증 / 파랑=신규추가항목
A33: ※ 모든 작업의 담당은 본인. Claude Code=코드구현 직접실행 / Claude=대화로 검토·설계보조 / Gemini=콘텐츠초안·교차검증보조(도구일 뿐, 최종 의사결정은 본인)

Sheet 체크리스트
A1: 3rd Host AI — 상세 체크리스트 (9단계 구조: 1,1.5,2,3,4,5,5.5,6,6.5)
A3: 단계 | B3: 카테고리 | C3: 세부 작업 | D3: 우선순위 | E3: 상태 | F3: 담당 / 활용도구 | G3: 날짜(요일) | H3: 비고
A4: 1 | B4: 데이터모델 설계(P0) | C4: Host-Property-Room-Bed 계층 스키마 확정(모두 optional) | D4: 최상 | E4: 완료 | F4: 본인 — Gemini(검토·콘텐츠 초안 보조) | G4: 2026-08-31(월) | H4: P0
A5: 1 | B5: 데이터모델 설계(P0) | C5: STEP0: DB명세서v1(3rd_host_ai_db_spec_v1.md)을 스키마 최종권위 문서로 확정 + 구버전 ERD(guests/payments 등 포함 폐기 초안) 폐기처리 | D5: 최상 | E5: 완료 | F5: 본인 — Claude(대화로 검토·설계 보조) | G5: 2026-08-31(월) | H5: 신규, 문서기준선(SSOT) 확정
A6: 1 | B6: 데이터모델 설계(P0) | C6: Property.accommodation_type 단일 ENUM 필드 확정 | D6: 최상 | E6: 완료 | F6: 본인 — Gemini(검토·콘텐츠 초안 보조) | G6: 2026-08-31(월) | H6: P0
A7: 1 | B7: 데이터모델 설계(P0) | C7: Reservation.bookable_unit_type(PROPERTY/ROOM/BED) 설계 | D7: 최상 | E7: 완료 | F7: 본인 — Gemini(검토·콘텐츠 초안 보조) | G7: 2026-09-01(화) | H7: P0
A8: 1 | B8: 데이터모델 설계(P0) | C8: PROPERTY 단위 예약시 하위 Room 전체 블록 인터셉터 로직 정의(본인 3룸숙소 실제케이스) | D8: 최상 | E8: 완료 | F8: 본인 — Gemini(검토·콘텐츠 초안 보조) | G8: 2026-09-01(화) | H8: P0
A9: 1 | B9: 데이터모델 설계(P0) | C9: reservation_status / refund_status 분리 설계 | D9: 최상 | E9: 완료 | F9: 본인 — Gemini(검토·콘텐츠 초안 보조) | G9: 2026-09-01(화) | H9: P0
A10: 1 | B10: 데이터모델 설계(P0) | C10: Reservation CHECK 제약(bookable_unit_type↔room_id/bed_id 조합) 확정 | D10: 최상 | E10: 완료 | F10: 본인 — Claude(대화로 검토·설계 보조) | G10: 2026-09-01(화) | H10: 간극항목1, DB명세서 2.6절 참고
A11: 1 | B11: 데이터모델 설계(P0) | C11: ROOMS/BEDS 계층 복합FK+UNIQUE + Reservation↔Channel/Room/Bed 동일Property 보장(통합확정) | D11: 최상 | E11: 완료 | F11: 본인 — Claude(대화로 검토·설계 보조) | G11: 2026-09-01(화) | H11: 간극항목2·6, DB명세서 2.6절 참고
A12: 1 | B12: 데이터모델 설계(P0) | C12: UNIQUE 복합제약 3종 확정(channel_connection_id+external_uid / property_id+target_month / property_id+channel) | D12: 상 | E12: 완료 | F12: 본인 — Gemini(검토·콘텐츠 초안 보조) | G12: 2026-09-01(화) | H12: 간극항목8, DB명세서 참고
A13: 1 | B13: 데이터모델 설계(P0) | C13: INQUIRY_RESPONSES 1:N + is_latest 플래그 설계 확정 | D13: 상 | E13: 완료 | F13: 본인 — Gemini(검토·콘텐츠 초안 보조) | G13: 2026-09-01(화) | H13: 간극항목7, 실제구현은 9/19
A14: 1 | B14: 데이터모델 설계(P0) | C14: FINANCIAL_CONFIGS→MONTHLY_SETTLEMENTS 관계 제거(스냅샷 분리) 확정 | D14: 상 | E14: 완료 | F14: 본인 — Gemini(검토·콘텐츠 초안 보조) | G14: 2026-09-01(화) | H14: 간극항목9, 실제구현은 10/5
... A39: 2 | B39: 기반 인프라 | C39: 로컬 개발 DB를 Docker Postgres로 전환 결정 및 세팅(MariaDB 대신, 문법불일치 리스크 원천차단) | D39: 최상 | E39: 완료 | F39: 본인 — Claude Code(터미널 직접실행 권장) | G39: 2026-09-05(토) | H39: 신규, MariaDB↔Postgres 이원화 리스크 제거
A40: 2 | B40: 기반 인프라 | C40: DB 스키마 구현(위 P0 설계 반영) | D40: 최상 | E40: 완료 | F40: 본인 — Claude Code(터미널 직접실행 권장) | G40: 2026-09-05(토)
A41: 2 | B41: 기반 인프라 | C41: GET /health 헬스체크 엔드포인트 구현(DB조회없이 즉시 응답, Render 슬립방지용 UptimeRobot 핑 대상) | D41: 상 | E41: 완료 | F41: 본인 — Claude Code(터미널 직접실행 권장) | G41: 2026-09-05(토) | H41: 신규, 9/3 API Contract v1.5 반영, 강사님 제안 검토로 발견
A42: 2 | B42: 기반 인프라 | C42: .env/.gitignore 초기 설정(API키·DB접속정보 분리, git 커밋 전 필수) | D42: 최상 | E42: 완료 | F42: 본인 — Claude Code(터미널 직접실행 권장) | G42: 2026-09-05(토) | H42: 신규, 보안 사전조치
A43: 6 | B43: 마무리 | C43: 녹화·편집 환경 설정(OBS 설정+편집툴 확정) | D43: 중 | E43: 완료 | F43: 본인 — Gemini(검토·콘텐츠 초안 보조) | G43: 2026-09-05(토) | H43: 신규, 편집도구 Canva/VEED 배제→Clipchamp 확정, docs/video_recording_setup.md 참고
A44: 6 | B44: 마무리 | C44: Clipchamp 10분 더미 영상 내보내기 테스트 | D44: 최상 | E44: 예정 | F44: 본인 — Gemini(검토·콘텐츠 초안 보조) | G44: 2026-10-07(수) | H44: 실패 시 Shotcut 전환
A45: 2 | B45: 기반 인프라 | C45: 통합 대시보드 뼈대(3~5개 숙소 한눈에 보기) | D45: 상 | E45: 완료 | F45: 본인 — Claude Code(터미널 직접실행 권장) | G45: 2026-09-08(화) | H45: Vite+React+TS+Tailwind 초기 세팅 포함(선행 작업, 별도 태스크 미생성). TypeScript로 구현하여 파일위치 .jsx→.tsx 정정.
A46: 2 | B46: 기반 인프라 | C46: iCal 연동 + ChannelConnection 구현(sync_status/last_synced_at 표시) | D46: 최상 | E46: 완료 | F46: 본인 — Claude Code(터미널 직접실행 권장) | G46: 2026-09-10(목) | H46: 실제 구현(Mock 아님)
A47: 2 | B47: 기반 인프라 | C47: 회원가입/로그인 화면+API 구현(JWT, 비밀번호는 bcrypt 해시로 저장) | D47: 최상 | E47: 완료 | F47: 본인 — Claude Code(터미널 직접실행 권장) | G47: 2026-09-11(금) | H47: 신규
A48: 2 | B48: 기반 인프라 | C48: 통합 캘린더 뷰: 독채=Property행 / 호스텔=Room 아코디언-Bed행 | D48: 상 | E48: 완료 | F48: 본인 — Claude Code(터미널 직접실행 권장) | G48: 2026-09-12(토)
A49: 2 | B49: 기반 인프라 | C49: iCal 동기화 시점 중복예약 충돌 감지 + 수동 새로고침 버튼 | D49: 상 | E49: 예정 | F49: 본인 — Claude Code(터미널 직접실행 권장) | G49: 2026-09-12(토) | H49: '실시간' 표현 금지
A50: 2 | B50: 기반 인프라 | C50: 네이버예약 채널카드 UI '내보내기 전용' 표시 | D50: 중 | E50: 예정 | F50: 본인 — Gemini(검토·콘텐츠 초안 보조) | G50: 2026-09-15(화) | H50: 네이버는 iCal 가져오기 미지원
A51: 2 | B51: 기반 인프라 | C51: 채널연결(iCal URL) 실패시 에러 안내 UI(잘못된 URL/파싱실패 케이스) | D51: 상 | E51: 예정 | F51: 본인 — Claude Code(터미널 직접실행 권장) | G51: 2026-09-16(수) | H51: 신규, 예외UX
A52: 2 | B52: 기반 인프라 | C52: Property 전체대여시 하위 Room 전체 블록 인터셉터 구현(본인 3룸숙소 핵심케이스) | D52: 최상 | E52: 완료 | F52: 본인 — Claude Code(터미널 직접실행 권장) | G52: 2026-09-14(월)
A53: 2 | B53: 기반 인프라 | C53: Room 전체대여시 하위 Bed 전체 블록 인터셉터 구현(호스텔 확장용) | D53: 중 | E53: 완료 | F53: 본인 — Claude Code(구현) / Gemini(검토) | G53: 2026-09-14(월) | H53: 1차 데모 강조점 아님
A54: 2 | B54: 기반 인프라 | C54: EXCLUDE USING GIST 겹침방지 제약조건 실제동작 테스트(겹침예약 insert시 DB레벨 차단 확인) | D54: 상 | E54: 완료 | F54: 본인 — Gemini(교차검증 보조) | G54: 2026-09-14(월) | H54: 신규, 배포환경 검증
A55: 2 | B55: 기반 인프라 | C55: ✅ 2단계 검증: 실제 iCal URL로 캘린더 반영·중복감지 정상동작 확인 | D55: 최상 | E55: 예정 | F55: 본인 — Gemini(교차검증 보조) | G55: 2026-09-15(화) | H55: 검증
A56: 6 | B56: 마무리 | C56: Vercel+Render+Supabase 스테이징=프로덕션 서비스 생성(뼈대 프로젝트로 CORS/env 연결 테스트, 10/8에 그대로 정식승격) | D56: 최상 | E56: 예정 | F56: 본인 — Claude Code(터미널 직접실행 권장) | G56: 2026-10-01(목) | H56: 정정(원래9/16→10/1), 750시간 한도 보존 위해 너무 일찍 만들지 않음, 카테고리도 기반인프라→마무리로 재분류(날짜범위 왜곡방지)
A57: 6 | B57: 마무리 | C57: .env.production 환경변수 설정(Vercel/Render/Supabase 키 분리) | D57: 상 | E57: 예정 | F57: 본인 — Gemini(교차검증 보조) | G57: 2026-10-01(목) | H57: 정정(원래9/16→10/1), 배포환경 검증, 카테고리 재분류
A58: 2 | B58: 기반 인프라 | C58: 로딩/에러/빈상태 공통 컴포넌트 적용 시작(캘린더 화면) | D58: 상 | E58: 완료 | F58: 본인 — Claude Code(터미널 직접실행 권장) | G58: 2026-09-16(수) | H58: 신규, Empty/Error UX · 9/14 완료(d181f34)
A59: 3 | B59: 고객 응대 자동화 | C59: 자체 통합 인박스(게스트 채팅 시뮬레이터 UI) | D59: 최상 | E59: 예정 | F59: 본인 — Claude Code(터미널 직접실행 권장) | G59: 2026-09-17(목) | H59: Mock UI
A60: 3 | B60: 고객 응대 자동화 | C60: 숙소별 RAG 지식베이스 구축(로컬 벡터검색, LLM비용無) + property_id 스코프 격리 + 개발용 응답캐시(동일질문 반복시 API 미호출) | D60: 최상 | E60: 예정 | F60: 본인 — Gemini(검토·콘텐츠 초안 보조) | G60: 2026-09-18(금) | H60: 실제 LLM 호출, 아키텍처: RAG검색(LLM비용0)→Claude 1회 통합호출(분류+위험도+다국어+근거 한번에 반환), 멀티스텝 분리 금지
A61: 3 | B61: 고객 응대 자동화 | C61: Claude API 초기설정: $5 선충전 + 월 Spend Limit $10 설정 + Dev/Prod API키 분리 | D61: 최상 | E61: 완료 | F61: 본인 — Claude Code(터미널 직접실행 권장) | G61: 2026-09-17(목) | H61: 신규, 비용통제 1
A62: 3 | B62: 고객 응대 자동화 | C62: LLM 응답 로딩/스켈레톤 UI(3~8초 지연 대응) | D62: 상 | E62: 예정 | F62: 본인 — Claude Code(터미널 직접실행 권장) | G62: 2026-09-18(금) | H62: 신규, 비동기UX 누락발견 반영
A63: 3 | B63: 고객 응대 자동화 | C63: AI 호출 재시도를 개별호출 2회로 제한(1문의=최대3 Claude호출) + 호출당 타임아웃(최초10초/재시도5초) | D63: 최상 | E63: 예정 | F63: 본인 — Claude Code(터미널 직접실행 권장) | G63: 2026-09-19(토) | H63: 신규, 비용통제 2 — 2026-09-01 크로스체크로 1회→2회 상향 확정. 9/15 정정: LangGraph 전제 제거(CLAUDE.md가 StateGraph 도입 금지 — 단일 호출 구조)
A64: 3 | B64: 고객 응대 자동화 | C64: AI 문의 엔드포인트 Rate Limit(IP당 분당10회) + LLM 사용량 로깅(토큰/지연/상태 기록) | D64: 상 | E64: 예정 | F64: 본인 — Claude Code(터미널 직접실행 권장) | G64: 2026-09-21(월) | H64: 신규, 비용통제 3
A65: 3 | B65: 고객 응대 자동화 | C65: AI/iCal 실패시 에러 Toast·Fallback 안내 처리 | D65: 상 | E65: 예정 | F65: 본인 — Claude Code(터미널 직접실행 권장) | G65: 2026-09-23(수) | H65: 신규
...

Sheet 9단계 검증 체크리스트
A1: 9단계 검증 체크리스트 (결과 확인 리스트)
A3: 단계 | B3: 검증 예정일 | C3: 결과 확인 리스트(Definition of Done) | D3: 판정 근거(9/9 추가)
A4: 1단계: 데이터모델(P0) | B4: 2026-09-04(금) | C4: □ Host-Property-Room-Bed 계층이 3룸숙소/호스텔 둘 다 표현되는가 □ ENUM/상태값 3종(reservation/refund/financial)이 분리됐는가 □ ERD와 API Contract가 실제 스키마와 일치하는가
A5: 1.5단계: UI/UX 설계 | B5: 2026-09-09(수) | C5: ☑ 11개 화면 목록에 빠진 화면이 없는가 ☑ 설계 문서(ui_design 6·7절)와 구현 계획이 실제 사용흐름과 맞는가 ☑ 공통 컴포넌트(Loading/Empty/Error/Toast)가 정의됐는가 ☑ 회원가입/로그인 플로우가 설계에 포함됐는가 | D5: ① ui_design 7-7 커버리지 표로 11개 라우트 전수 확인 ② 후보 25건 추출, 3회 독립 크로스체크로 판정 — 완료 9 / 종결·흡수 4 / 부분 3 / 미완 9. 미완은 전부 착수일 지정하여 이월 ③ ui_design 5-9절. 9/9에 폼 화면용 어휘(입력대기/제출중/실패/성공)를 추가로 분리 ④ api_contract v2.3, ui_design 4-1·4-2·7-2, 401 정책 1-6
A6: 2단계: 기반 인프라 | B6: 2026-09-15(화) | C6: □ 실제 iCal URL로 캘린더 반영/중복감지가 되는가 □ 3룸 전체예약시 하위 Room이 모두 블록되는가 □ 스테이징 배포(Vercel/Render/Supabase)가 조기에 연결됐는가 □ '실시간' 표현이 남아있지 않은가
A7: 3단계: 고객 응대 자동화 | B7: 2026-09-27(일) | C7: □ 교차오답 없이 숙소별로 정확히 분리되는가 □ 영/중/일 응답이 자연스러운가 □ LLM 응답지연시 스켈레톤/로딩 UI가 뜨는가 □ API 실패시 에러 UI가 뜨는가(빈화면 아님)
A8: 4단계: 체크인+청소 | B8: 2026-10-03(토) | C8: □ 체크아웃→청소생성→상태전이가 정상 흐르는가 □ 예약변경시 청소시간이 재계산되는가 □ Empty/Error 상태가 청소·체크인 화면에도 적용됐는가
A9: 5단계: 정산·가격·알림·컴플라이언스 | B9: 2026-10-07(수) | C9: □ 정산 3단계 파이프라인이 실데이터로 재현되는가 □ 취소/환불이 매출에서 자동 제외되는가 □ Action Center가 규칙대로만 트리거되는가(AI판단 없이) □ 시드데이터가 정상 반영됐는가
A10: 5.5단계: 통합QA·보안 | B10: 2026-10-08(목) | C10: □ 전체 플로우 회귀테스트를 통과했는가 □ 중복예약/취소/API실패 등 예외케이스 에러UI를 확인했는가 □ 비밀번호 해시/.env/GitHub secret 노출이 없는가 □ 모든 Mock 기능에 '시뮬레이션' 뱃지가 표시되는가 □ README가 작성됐는가
A11: 6단계: 마무리 | B11: 2026-10-10(토) | C11: □ 프로덕션 배포본이 실제로 접속되는가 □ 슬라이드/영상에 Mock/Real 표현 오류가 없는가 □ 영상 음성 나레이션이 끝까지 정상 재생되는가 □ 제출 포맷/용량이 요건에 맞는가
A12: 6.5단계: 최종 데모검증 | B12: 2026-10-11(일) | C12: □ 시드데이터 재실행 후 데모 데이터가 깨끗한가 □ E2E 시나리오(로그인→...→정산)가 끊김없이 진행되는가 □ 발표 당일(10/12) 웜업 절차를 확인했는가 — 전날 웨이크업은 15분 뒤 무효 □ 예상 Q&A 답변이 준비됐는가 □ 발표영상 실제 재생 확인(음성·화면 끝까지 끊김없이 재생되는지)
A15: 일자별 할 일 리스트
A16: 날짜(요일) | B16: 단계 | C16: 주간(본인+Claude·구현) | D16: 야간(본인+Gemini·기획/콘텐츠) | E16: 비고
A17: 2026-08-31(월) | B17: 1단계 | C17: □ [신규] STEP0: DB명세서v1(3rd_host_ai_db_spec_v1.md)을 스키마 최종권위 문서로 확정 + 구버전 ERD(guests/payments 등 포함 폐기 초안) 폐기처리 | D17: □ [P0] Host-Property-Room-Bed 계층 스키마 확정(모두 optional) □ [P0] Property.accommodation_type 단일 ENUM 필드 확정
A18: 2026-09-01(화) | B18: 1단계 | C18: □ Reservation CHECK 제약(bookable_unit_type↔room_id/bed_id 조합) 확정 □ ROOMS/BEDS 계층 복합FK+UNIQUE + Reservation↔Channel/Room/Bed 동일Property 보장(통합확정) | D18: □ [P0] Reservation.bookable_unit_type(PROPERTY/ROOM/BED) 설계 □ [P0] PROPERTY 단위 예약시 하위 Room 전체 블록 인터셉터 로직 정의(본인 3룸숙소 실제케이스) □ [P0] reservation_status / refund_status 분리 설계 □ UNIQUE 복합제약 3종 확정(channel_connection_id+external_uid / property_id+target_month / property_id+channel) □ INQUIRY_RESPONSES 1:N + is_latest 플래그 설계 확정 □ FINANCIAL_CONFIGS→MONTHLY_SETTLEMENTS 관계 제거(스냅샷 분리) 확정 □ [신규] 제출용 기획서 초안 작성(주제/선정이유/일정표/기술스택 — 기존 대화내용 취합)
A19: 2026-09-02(수) | B19: 1단계 | C19: □ [P0] Property 단위 데이터 격리 원칙 확정(KB/Reservation/Checklist/SmartLock 전체) □ [신규] DB명세서↔ERD↔체크리스트 3문서 최종 동기화 확인 □ [신규] 기획서 최종 검토 및 다듬기 □ [신규] Azure Cloud 서비스 확인 완료 → Render로 최종 확정(Azure 전환 안함) □ [신규] Google AI Studio 무료 Gemini API키 미리 발급(백업용, 5분 소요, 스택변경 아님) | D19: □ [P0] financial_status(ESTIMATED/CONFIRMED/MANUALLY_ADJUSTED) 필드 설계 □ [P0] 날짜 5종 분리 확정(booked_at/check_in/check_out/expected_settlement_at/actual_settlement_at) □ [P0] ChannelConnection 모델 설계(channel/external_property_id/sync_status/last_synced_at) □ [P0] ChecklistTemplate.renewal_trigger_type(NONE/EXPIRATION_BASED/EVENT_BASED) 필드 추가 □ ACTION_ITEMS 중복생성 idempotency 정책 문서화(동일 reservation_id+category+OPEN 재사용) □ risk_level '규칙기반 우선순위'로 문서화(법적판단 아님 명시) □ 인덱스 요구사항 목록화(property_id 계열 전체+ActionCenter 복합인덱스, 실제생성은 9/5)
A20: 2026-09-03(목) | B20: 1단계 | C20: □ [신규] ✅ 기획서 제출(오전 11시 마감 — 주제/선정이유/일정표/기술스택 포함) | D20: □ [신규] ERD 다이어그램 작성(전체 엔티티 관계도) □ [신규] API Contract(엔드포인트 목록·요청/응답 스펙) 정의 □ [신규] 상태전이/이벤트 구조 다이어그램 정리(예약→청소→정산→알림 연결)
A21: 2026-09-04(금) | B21: 1단계 | C21: □ [검증] ✅ 1단계 검증: 스키마+ERD+API Contract 대조 확인 | D21: -
A22: 2026-09-05(토) | B22: 2단계,6단계 | C22: □ [신규] 로컬 개발 DB를 Docker Postgres로 전환 결정 및 세팅(MariaDB 대신, 문법불일치 리스크 원천차단) □ DB 스키마 구현(위 P0 설계 반영) □ [신규] GET /health 헬스체크 엔드포인트 구현(DB조회없이 즉시 응답, Render 슬립방지용 UptimeRobot 핑 대상) □ [신규] .env/.gitignore 초기 설정(API키·DB접속정보 분리, git 커밋 전 필수) | D22: □ [신규] 녹화·편집 환경 설정(OBS 설정+편집툴 확정)
A23: 2026-09-07(월) | B23: 1.5단계 | C23: - | D23: □ [신규] 전체 화면목록 확정(로그인·회원가입·온보딩2스텝·대시보드·캘린더·AI인박스·액션센터·청소·정산·컴플라이언스(설정탭)·지식베이스·설정) □ [신규] 핵심 화면 와이어프레임 제작(대시보드·예약모달·AI인박스·정산·온보딩) □ [신규] 디자인시스템 공통 컴포넌트 정의(Header/Sidebar/Card/Badge/Modal/Toast/Loading/EmptyState) | E23: 🌙 연장근무일(+3h)
A24: 2026-09-08(화) | B24: 2단계 | C24: ☑ 통합 대시보드 뼈대(3~5개 숙소 한눈에 보기) | D24: -
A25: 2026-09-09(수) | B25: 1.5단계 | C25: ☑ [신규] 회원가입/로그인 화면+API 설계(JWT) ☑ [검증] ✅ 1.5단계 검증: 와이어프레임 실제 흐름대로 클릭 시뮬레이션 리뷰 | D25: ☑ [신규] User Flow 다이어그램 작성(화면간 이동 구조) | E25: 🌙 연장근무일(+3h) ※ User Flow는 D열(야간·Gemini)에 있으나 실제로는 Claude Code가 주간에 작성. 열은 옮기지 않았다(9/9).
A26: 2026-09-10(목) | B26: 2단계 | C26: ☑ iCal 연동 + ChannelConnection 구현(sync_status/last_synced_at 표시) | D26: -
A27: 2026-09-11(금) | B27: 2단계 | C27: ☑ [신규] 회원가입/로그인 화면+API 구현(JWT, 비밀번호는 bcrypt 해시로 저장) | D27: - | E27: 🌙 연장근무일(+3h)
A28: 2026-09-12(토) | B28: 2단계 | C28: ☑ 통합 캘린더 뷰: 독채=Property행 / 호스텔=Room 아코디언-Bed행 □ iCal 동기화 시점 중복예약 충돌 감지 + 수동 새로고침 버튼 | D28: -
A29: 2026-09-14(월) | B29: 2단계 | C29: ☑ Property 전체대여시 하위 Room 전체 블록 인터셉터 구현(본인 3룸숙소 핵심케이스) ☑ [검증] EXCLUDE USING GIST 겹침방지 제약조건 실제동작 테스트(겹침예약 insert시 DB레벨 차단 확인) | D29: ☑ Room 전체대여시 하위 Bed 전체 블록 인터셉터 구현(호스텔 확장용) | E29: 🌙 연장근무일(+3h)
A30: 2026-09-15(화) | B30: 2단계 | C30: □ [검증] ✅ 2단계 검증: 실제 iCal URL로 캘린더 반영·중복감지 정상동작 확인 | D30: □ 네이버예약 채널카드 UI '내보내기 전용' 표시
A31: 2026-09-16(수) | B31: 2단계 | C31: □ [신규] 채널연결(iCal URL) 실패시 에러 안내 UI(잘못된 URL/파싱실패 케이스) ☑ [신규] 로딩/에러/빈상태 공통 컴포넌트 적용 시작(캘린더 화면) | D31: -
A32: 2026-09-17(목) | B32: 3단계 | C32: □ 자체 통합 인박스(게스트 채팅 시뮬레이터 UI) ☑ [신규] Claude API 초기설정: $5 선충전 + 월 Spend Limit $10 설정 + Dev/Prod API키 분리 | D32: -
A33: 2026-09-18(금) | B33: 3단계 | C33: □ [신규] LLM 응답 로딩/스켈레톤 UI(3~8초 지연 대응) | D33: □ 숙소별 RAG 지식베이스 구축(로컬 벡터검색, LLM비용無) + property_id 스코프 격리 + 개발용 응답캐시(동일질문 반복시 API 미호출) | E33: 🌙 연장근무일(+3h)
A34: 2026-09-19(토) | B34: 3단계 | C34: □ [신규] AI 호출 재시도를 개별호출 2회로 제한(1문의=최대3 Claude호출) + 호출당 타임아웃(최초10초/재시도5초) □ 문의 자동분류(예약/체크인/컴플레인/일반) | D34: -
A35: 2026-09-21(월) | B35: 3단계 | C35: □ [신규] AI 문의 엔드포인트 Rate Limit(IP당 분당10회) + LLM 사용량 로깅(토큰/지연/상태 기록) □ 외국인 게스트 언어 자동감지 + 다국어(영/중/일) 응답 생성 | D35: - | E35: 🌙 연장근무일(+3h)
A36: 2026-09-22(화) | B36: 3단계 | C36: □ 체크인/체크아웃 안내, 리뷰요청 자동화 | D36: □ 위험도 분류 적용(자동:와이파이/체크인시간/주차/비번 vs 승인필요:환불/변경/할인/보상/민원/고장/안전)
A37: 2026-09-23(수) | B37: 3단계 | C37: □ [신규] AI/iCal 실패시 에러 Toast·Fallback 안내 처리 □ AI 답변 '근거' 표시 UI(참고 KB 나열) + 마크다운 렌더링 처리 □ [신규] 예약 상세화면→AI대화내역→Action Center 처리이력으로 이어지는 통합 딥링크/단일플로우 구현 □ [신규] 중간 회귀체크포인트1: 1~3단계 기능 통합 재확인(예약→AI응대까지 흐름 재실행) | D37: - | E37: 🌙 연장근무일(+3h)
A38: 2026-09-24(목) | B38: 3단계,4단계 | C38: □ [검증] ✅ 3단계 검증: 교차오답 테스트 + 의도적 API실패 유발후 에러UI 확인 | D38: □ 청소 상태머신 구현(PENDING→ASSIGNED→IN_PROGRESS→COMPLETED→VERIFIED/ISSUE)
A39: 2026-09-25(금) | B39: 4단계 | C39: □ 예약확정시 임시 비밀번호 자동생성/만료 로직 □ [신규] 예약확정 시점 청소작업 선제생성 로직(scheduled_at=체크아웃 시각, 9/3 크로스체크로 시점 정정 — 전날알림 기능 성립을 위해 필요) □ 예약변경시 청소시간 자동 재계산 로직 | D39: -
A40: 2026-09-26(토) | B40: 4단계 | C40: □ [신규] Empty State/에러처리 청소·체크인 화면 반영 □ 스마트락 100% Mock 확정 + '시뮬레이션' 뱃지 표시 □ Mock 락 상태 대시보드(잠김/열림/배터리) | D40: - | E40: 🗓 근무일 — 명절휴무는 9/24~25뿐(최종 스펙 요약 B22)
A41: 2026-09-28(월) | B41: 4단계 | C41: □ 문자API(알리고 등) 청소업체 알림 자동발송 □ 체크리스트+사진업로드 완료확인(VERIFIED 단계) | D41: □ 호스텔 객실(Room)단위 정비 체크리스트 + 비품부족 체크박스 | E41: 🌙 연장근무일(+3h)
A42: 2026-09-29(화) | B42: 4단계,5단계 | C42: □ [검증] ✅ 4단계 검증: 체크아웃→청소생성→상태전이 전체 흐름 1회 시뮬레이션 | D42: □ 채널별 수수료 템플릿 설계(Airbnb 15.5%, Booking.com 15~18% 등)
A43: 2026-09-30(수) | B43: 5단계 | C43: □ 1단계 자동추정 로직(Room 기본단가×박수-수수료) □ 취소/환불 반영 로직(refund_status 연동, 매출 자동제외) | D43: - | E43: 🌙 연장근무일(+3h)
...

Sheet 일자별 실행리스트(파일위치)
A1: 3rd Host AI — 일자별 실행리스트 (구분·파일위치·핵심포인트·주의점·확인방법)
A3: 날짜(요일) | B3: 단계 | C3: 구분 | D3: 카테고리 | E3: 세부 작업 | F3: 담당/활용도구 | G3: 파일 위치 | H3: 가장 중요한 포인트 | I3: 주의할 점 | J3: 완벽 확인방법
A4: 2026-08-31(월) | B4: 1단계 | C4: 문서확인 | D4: 데이터모델 설계(P0) | E4: Host-Property-Room-Bed 계층 스키마 확정(모두 optional) | F4: 본인 — Gemini(검토·콘텐츠보조) | G4: docs/3rd_host_ai_db_spec_v1.md (2.1~2.4절) | H4: 독채(3룸통대여)와 호스텔(개별실판매)을 하나의 구조로 동시 표현하는 것이 핵심 차별화 | I4: Room/Bed를 모두 optional로 둬야 함 — 강제로 NOT NULL 만들면 독채 예약 자체를 표현 못함 | J4: 3룸숙소=Property단위, 호스텔=Room단위 두 시나리오 모두 예약 생성이 가능한지 확인
A5: 2026-08-31(월) | B5: 1단계 | C5: 문서확인 | D5: 데이터모델 설계(P0) | E5: STEP0: DB명세서v1(3rd_host_ai_db_spec_v1.md)을 스키마 최종권위 문서로 확정 + 구버전 ERD(guests/payments 등 포함 폐기 초안) 폐기처리 | F5: 본인 — Claude(대화보조) | G5: docs/3rd_host_ai_db_spec_v1.md (전체) | H5: DB명세서에 이미 결정된 내용을 그대로 반영하는 단계 — 새로 고민하지 않는다 | I5: 임의로 필드나 값을 추가하지 않는다(범위확장 방지 원칙) | J5: DB명세서 해당 섹션과 실제 반영내용을 나란히 놓고 비교
A6: 2026-08-31(월) | B6: 1단계 | C6: 문서확인 | D6: 데이터모델 설계(P0) | E6: Property.accommodation_type 단일 ENUM 필드 확정 | F6: 본인 — Gemini(검토·콘텐츠보조) | G6: docs/3rd_host_ai_db_spec_v1.md (1. ENUM 타입 정의) | H6: 단일 ENUM(한 공간에 복수 숙박업 유형 등록은 법적으로 불가능하다고 확인됨) | I6: 6개 값 정확히(URBAN_HOMESTAY,RURAL_HOMESTAY,HANOK,HOSTEL,LODGING_FACILITY,GENERAL_LODGING) — PENSION/OTHER/HANOK_STAY 같은 임의값 절대 금지 | J6: DB명세서 1절 ENUM 정의와 실제 반영값을 한 글자씩 diff 비교
A7: 2026-09-01(화) | B7: 1단계 | C7: 문서확인 | D7: 데이터모델 설계(P0) | E7: Reservation.bookable_unit_type(PROPERTY/ROOM/BED) 설계 | F7: 본인 — Gemini(검토·콘텐츠보조) | G7: docs/3rd_host_ai_db_spec_v1.md (2.2 PROPERTIES / 2.6 RESERVATIONS) | H7: PROPERTY/ROOM/BED 3종 판매단위를 하나의 Reservation 테이블로 표현 | I7: 이 값과 room_id/bed_id 실사용 일치여부는 DB CHECK로 못 잡음(다른 테이블이라 PostgreSQL 일반 CHECK 불가) — 반드시 애플리케이션 검증 필요 | J7: bookable_unit_type=PROPERTY인데 room_id가 채워진 예약을 일부러 넣어보고 애플리케이션이 막는지 테스트
A8: 2026-09-01(화) | B8: 1단계 | C8: 문서확인 | D8: 데이터모델 설계(P0) | E8: PROPERTY 단위 예약시 하위 Room 전체 블록 인터셉터 로직 정의(본인 3룸숙소 실제케이스) | F8: 본인 — Gemini(검토·콘텐츠보조) | G8: docs/3rd_host_ai_db_spec_v1.md (2.6.1 예약 겹침 방지) | H8: 본인 3룸숙소의 실제 운영형태(통대여)를 반영하는 핵심 로직 | I8: EXCLUDE 제약만으로는 PROPERTY예약↔ROOM/BED예약 교차충돌을 못 막음 — 반드시 트랜잭션 검증 코드로 방어 | J8: 3룸 전체예약 확정 후 그 중 방 1개만 별도 예약 시도 → 반드시 차단되는지 확인
A9: 2026-09-01(화) | B9: 1단계 | C9: 문서확인 | D9: 데이터모델 설계(P0) | E9: reservation_status / refund_status 분리 설계 | F9: 본인 — Gemini(검토·콘텐츠보조) | G9: docs/3rd_host_ai_db_spec_v1.md (2.6 RESERVATIONS 컬럼) | H9: '투숙완료(COMPLETED)'와 '부분환불(PARTIAL)'을 동시에 표현할 수 있어야 함 | I9: 하나의 status 컬럼으로 합치면 이 조합 자체를 표현할 수 없음 | J9: COMPLETED+PARTIAL 조합을 실제로 저장해보고 정상 저장되는지 확인
A10: 2026-09-01(화) | B10: 1단계 | C10: 문서확인 | D10: 데이터모델 설계(P0) | E10: Reservation CHECK 제약(bookable_unit_type↔room_id/bed_id 조합) 확정 | F10: 본인 — Claude(대화보조) | G10: docs/3rd_host_ai_db_spec_v1.md (2.2 PROPERTIES / 2.6 RESERVATIONS) | H10: room_id/bed_id 조합의 '내부 형태'만 DB가 검증 가능 | I10: PostgreSQL CHECK는 다른 테이블(PROPERTIES) 값을 볼 수 없음 — bookable_unit_type과의 교차일치는 앱 책임임을 반드시 인지 | J10: 유효하지 않은 조합(bed_id만 있고 room_id는 NULL 등) INSERT 시도 → DB가 거부하는지
A11: 2026-09-01(화) | B11: 1단계 | C11: 문서확인 | D11: 데이터모델 설계(P0) | E11: ROOMS/BEDS 계층 복합FK+UNIQUE + Reservation↔Channel/Room/Bed 동일Property 보장(통합확정) | F11: 본인 — Claude(대화보조) | G11: docs/3rd_host_ai_db_spec_v1.md (2.3 ROOMS / 2.4 BEDS / 2.6 RESERVATIONS (A)) | H11: 다른 숙소 소속 Room을 잘못 참조하는 데이터오염을 DB가 원천 차단 | I11: UNIQUE(room_id,property_id)는 중복방지용이 아니라 복합FK 참조용 후보키 — room_name/bed_label UNIQUE가 실제 중복방지 역할 | J11: Property A 소속 room_id를 Property B의 예약에 넣어보고 FK 위반으로 거부되는지 확인
A12: 2026-09-01(화) | B12: 1단계 | C12: 문서확인 | D12: 데이터모델 설계(P0) | E12: UNIQUE 복합제약 3종 확정(channel_connection_id+external_uid / property_id+target_month / property_id+channel) | F12: 본인 — Gemini(검토·콘텐츠보조) | G12: docs/3rd_host_ai_db_spec_v1.md (2.5 / 2.6 / 2.8절) | H12: 플랫폼별 예약UID/월별정산/채널연결 각각 중복 방지 | I12: 채널당 연결 1개 제한은 이번 MVP 한정 — 향후 여러 리스팅 대응은 2차 과제 | J12: 같은 property+channel 조합을 2번 생성 시도했을 때 에러가 나는지 확인
A13: 2026-09-01(화) | B13: 1단계 | C13: 문서확인 | D13: 데이터모델 설계(P0) | E13: INQUIRY_RESPONSES 1:N + is_latest 플래그 설계 확정 | F13: 본인 — Gemini(검토·콘텐츠보조) | G13: docs/3rd_host_ai_db_spec_v1.md (2.12 INQUIRY_RESPONSES) | H13: 재시도/재답변 이력을 보존하는 1:N + is_latest 구조 | I13: 새 응답을 만들 때 기존 is_latest를 먼저 false로 바꾸는 걸 빠뜨리면 부분UNIQUE 인덱스 위반 에러 발생 | J13: 같은 문의에 응답 2번 생성 후 is_latest=true인 행이 정확히 1개인지 쿼리로 확인
A14: 2026-09-01(화) | B14: 1단계 | C14: 문서확인 | D14: 데이터모델 설계(P0) | E14: FINANCIAL_CONFIGS→MONTHLY_SETTLEMENTS 관계 제거(스냅샷 분리) 확정 | F14: 본인 — Gemini(검토·콘텐츠보조) | G14: docs/3rd_host_ai_db_spec_v1.md (2.7 FINANCIAL_CONFIGS / 2.8 MONTHLY_SETTLEMENTS) | H14: 정산은 스냅샷 — 수수료율이 나중에 바뀌어도 과거 정산결과는 불변이어야 함 | I14: FINANCIAL_CONFIGS와 직접 FK로 연결하면 안 됨. applied_commission_rate 컬럼에 계산 당시 값을 별도로 저장 | J14: 수수료율을 0.155→0.16으로 바꾼 뒤, 과거 정산행의 applied_commission_rate가 여전히 0.155인지 확인
... A106: 2026-10-05(월) | B106: 5단계 | C106: 코드구현 | D106: 컴플라이언스 | E106: ✅ 5단계 검증: 정산 3단계 파이프라인 + 알림센터 트리거 실데이터로 재현 | F106: 본인 — Claude Code(터미널 직접실행 권장) | G106: backend/ 또는 frontend/ (세부 위치는 해당일 착수시 확정) | H106: 자동추정→일괄확인→예외보정 3단계로 수작업을 최소화(엑셀 수기정산과 다르게 만드는 것이 목표) | I106: iCal에는 결제정보가 없어 모든 금액이 추정치 — financial_status(ESTIMATED/CONFIRMED/MANUALLY_ADJUSTED)로 신뢰도를 반드시 구분표시 | J106: 전체 예약 중 예외건(할인적용 등)만 수동수정하고 나머지는 1클릭으로 끝나는지 확인
A107: 2026-10-06(화) | B107: 6단계 | C107: 신규작성 | D107: 마무리 | E107: 발표 슬라이드 초안 작성(구성·화면 캡처·AI Agent Loop 다이어그램) | F107: 본인 — Gemini(검토·콘텐츠보조) | G107: 발표자료(PPTX)
A108: 2026-10-06(화) | B108: 6단계 | C108: 신규작성 | D108: 마무리 | E108: 제출용 설명문서 최종본 정리(9/3 기획서 확장판: 배경/주제/기술스택/아키텍처/사용법) | F108: 본인 — Gemini(검토·콘텐츠보조) | G108: docs/project_plan_draft.md (신규생성) | H108: Feature Freeze 이후에는 로직 변경 없이 텍스트·설정만 수정 | I108: 제출 직전 급하게 뭔가 더 고치려는 유혹을 참는다 | J108: 최종 산출물(배포본/영상/문서)을 처음부터 끝까지 직접 재생·재확인
A109: 2026-10-07(수) | B109: 6단계 | C109: 설계/콘텐츠 | D109: 마무리 | E109: Clipchamp 10분 더미 영상 내보내기 테스트 | F109: 본인 — Gemini(검토·콘텐츠보조) | G109: 외부(Clipchamp) | H109: Feature Freeze 이후에는 로직 변경 없이 텍스트·설정만 수정 | I109: 제출 직전 급하게 뭔가 더 고치려는 유혹을 참는다 | J109: 최종 산출물(배포본/영상/문서)을 처음부터 끝까지 직접 재생·재확인
A110: 2026-10-07(수) | B110: 6단계 | C110: 설계/콘텐츠 | D110: 마무리 | E110: 영상 대본/콘티 초안 작성(화면 흐름·나레이션 포인트 먼저 잡기, 최종 코드 완성 전에도 가능) | F110: 본인 — Gemini(검토·콘텐츠보조) | G110: docs/video_script.md | H110: Feature Freeze 이후에는 로직 변경 없이 텍스트·설정만 수정 | I110: 제출 직전 급하게 뭔가 더 고치려는 유혹을 참는다 | J110: 최종 산출물(배포본/영상/문서)을 처음부터 끝까지 직접 재생·재확인
A111: 2026-10-08(목) | B111: 5.5단계 | C111: 코드구현 | D111: 통합QA·보안 | E111: 전체 기능 회귀테스트(예약→청소→AI→정산→알림 전체 플로우 1회 통관) | F111: 본인 — Claude Code(터미널 직접실행 권장) | G111: backend/tests/test_full_flow.py | H111: 자동추정→일괄확인→예외보정 3단계로 수작업을 최소화(엑셀 수기정산과 다르게 만드는 것이 목표) | I111: iCal에는 결제정보가 없어 모든 금액이 추정치 — financial_status(ESTIMATED/CONFIRMED/MANUALLY_ADJUSTED)로 신뢰도를 반드시 구분표시 | J111: 전체 예약 중 예외건(할인적용 등)만 수동수정하고 나머지는 1클릭으로 끝나는지 확인
A112: 2026-10-08(목) | B112: 5.5단계 | C112: 코드구현 | D112: 통합QA·보안 | E112: 예외케이스 전수점검(중복예약/취소/환불/iCal실패/LLM실패/DB실패 에러UI 확인) | F112: 본인 — Claude Code(터미널 직접실행 권장) | G112: backend/app/services/ical_sync.py | H112: 배포 전 마지막 방어선 — 여기서 놓치면 발표 중 사고로 직결 | I112: 체크리스트 일부만 하지 말고 전체 시나리오를 빠짐없이 재현 | J112: 각 항목을 실제로 테스트해보고 결과를 기록
A113: 2026-10-08(목) | B113: 5.5단계 | C113: 코드구현 | D113: 통합QA·보안 | E113: 보안점검: 비밀번호 해시 확인, .env/GitHub secret 노출여부 검색 | F113: 본인 — Claude Code(터미널 직접실행 권장) | G113: backend/app/core/security.py | H113: 배포 전 마지막 방어선 — 여기서 놓치면 발표 중 사고로 직결 | I113: 체크리스트 일부만 하지 말고 전체 시나리오를 빠짐없이 재현 | J113: 각 항목을 실제로 테스트해보고 결과를 기록
A114: 2026-10-08(목) | B114: 5.5단계 | C114: 코드구현 | D114: 통합QA·보안 | E114: Real/Mock UI 라벨 전수 확인(스마트락/가격반영/OTA메시징 '시뮬레이션' 표시) | F114: 본인 — Claude Code(터미널 직접실행 권장) | G114: backend/app/services/doorlock_mock.py | H114: 1개도 실연동 시도하지 않고 개발 착수부터 100% Mock으로 확정(시간 확보) | I114: 화면에 '시뮬레이션'임을 명확히 표시해야 함 — 실제 연동처럼 보이면 심사 시 오해 소지 | J114: 화면에 Mock 뱃지가 육안으로 확인되는지
A115: 2026-10-08(목) | B115: 5.5단계 | C115: 설계/콘텐츠 | D115: 통합QA·보안 | E115: README.md 작성(소개/아키텍처/스택/설치법/환경변수/Demo계정/Real·Mock범위) | F115: 본인 — Gemini(검토·콘텐츠보조) | G115: README.md | H115: 배포 전 마지막 방어선 — 여기서 놓치면 발표 중 사고로 직결 | I115: 체크리스트 일부만 하지 말고 전체 시나리오를 빠짐없이 재현 | J115: 각 항목을 실제로 테스트해보고 결과를 기록
A116: 2026-10-08(목) | B116: 6단계 | C116: 코드구현 | D116: 마무리 | E116: GitHub 저장소 최종정리 + 프로덕션 배포 전환(스테이징→정식)+CORS 최종확인 | F116: 본인 — Claude Code(터미널 직접실행 권장) | G116: 전체 저장소 | H116: Feature Freeze 이후에는 로직 변경 없이 텍스트·설정만 수정 | I116: 제출 직전 급하게 뭔가 더 고치려는 유혹을 참는다 | J116: 최종 산출물(배포본/영상/문서)을 처음부터 끝까지 직접 재생·재확인
A117: 2026-10-09(금) | B117: 5.5단계 | C117: 코드구현 | D117: 통합QA·보안 | E117: 1920x1080 데스크톱+Chrome 기준 화면 확인 | F117: 본인 — Claude Code(터미널 직접실행 권장) | G117: frontend/ (브라우저 확인, 파일아님) | H117: 배포 전 마지막 방어선 — 여기서 놓치면 발표 중 사고로 직결 | I117: 체크리스트 일부만 하지 말고 전체 시나리오를 빠짐없이 재현 | J117: 각 항목을 실제로 테스트해보고 결과를 기록
A118: 2026-10-09(금) | B118: 6단계 | C118: 코드구현 | D118: 마무리 | E118: Mock/Real 표현 최종점검 + '숙소운영특화 AI Agent' 표현 일관성 점검 | F118: 본인 — Claude Code(터미널 직접실행 권장) | G118: frontend/src/ (전체 텍스트 검수) | H118: Feature Freeze 이후에는 로직 변경 없이 텍스트·설정만 수정 | I118: 제출 직전 급하게 뭔가 더 고치려는 유혹을 참는다 | J118: 최종 산출물(배포본/영상/문서)을 처음부터 끝까지 직접 재생·재확인
A119: 2026-10-09(금) | B119: 6단계 | C119: 문서확인 | D119: 마무리 | E119: 발표 슬라이드 최종본 확정(AI Agent Loop 다이어그램 포함) | F119: 본인 직접(콘텐츠 확인/검토, 코드작업 아님) | G119: docs/presentation.pptx (외부) | H119: Feature Freeze 이후에는 로직 변경 없이 텍스트·설정만 수정 | I119: 제출 직전 급하게 뭔가 더 고치려는 유혹을 참는다 | J119: 최종 산출물(배포본/영상/문서)을 처음부터 끝까지 직접 재생·재확인
... A131: 2026-10-11(일) | B131: 6.5단계 | C131: 코드구현 | D131: 마무리 | E131: ✅ 발표자료(PPT) PBT 제출(외부마감 10/11) | F131: 본인 — Claude Code(터미널 직접실행 권장) | G131: 제출플랫폼(외부) | H131: 발표 당일 사고 예방이 유일한 목적 | I131: 시연 직전 반드시 실제 환경에서 리허설한다(로컬 테스트만으로 안심 금지) | J131: 처음부터 끝까지 실제로 클릭해보며 끊기는 지점이 없는지 확인
A133: ※ 구분 범례
A134: 문서확인 | B134: 이미 DB명세서 등에 작성된 내용을 재확인·체크만
A135: 신규작성 | B135: 아직 없는 문서를 새로 작성
A136: 설정확인 | B136: 파일이 아닌 클라우드 콘솔 등 외부 설정 확인
A137: 코드구현 | B137: 실제 backend/frontend 코드 작성(9/5 이후만 해당)
A138: 설계/콘텐츠 | B138: 야간 시간대 문서·콘텐츠 초안 작업
A139: 2026-09-16(수) | B139: 3단계 | C139: 코드구현 | D139: 고객 응대 자동화 | E139: N1 AI 패키지 도입(anthropic·sentence-transformers) + services/ai/ 골격 | F139: 본인 — Claude Code(터미널 직접실행 권장) | G139: backend/requirements.txt, backend/app/services/ai/__init__.py | H139: EMBEDDING_DIM=384에 맞는 모델만 쓴다 — paraphrase-multilingual-MiniLM-L12-v2(한국어 하우스룰 + 영/중/일 문의를 같은 공간에) | I139: 유료 임베딩 API를 쓰지 않는다(CLAUDE.md). torch 포함 약 1GB가 늘어 Render 배포 크기에 영향 — 10/1 배포 전 확인 | J139: python -c로 384차원이 나오는지 + anthropic 호출 1건이 200으로 돌아오는지 둘 다 확인
A140: 2026-09-16(수) | B140: 2단계 | C140: 코드구현 | D140: 기반 인프라 | E140: N8 /settings 채널연동 탭 화면(연결 목록·등록·삭제·수동 동기화) | F140: 본인 — Claude Code(터미널 직접실행 권장) | G140: frontend/src/pages/Settings.tsx | H140: 이 화면이 없으면 r49(수동 새로고침)·r50(네이버 카드)·r51(에러 UI) 셋이 붙을 자리가 없다 | I140: iCal URL은 마스킹해서 보여준다(api_contract 3절 ical_url_masked). 전체 URL을 화면에 그대로 찍지 않는다 | J140: 브라우저에서 로딩·에러·빈 상태 세 가지를 눈으로 본다(화면 작업 규칙 완료 조건)
A141: 2026-09-18(금) | B141: 3단계 | C141: 코드구현 | D141: 고객 응대 자동화 | E141: N2 rag_engine.py — pgvector 코사인 검색 + property_id 물리 격리 | F141: 본인 — Claude Code(터미널 직접실행 권장) | G141: backend/app/services/ai/rag_engine.py | H141: WHERE property_id = :pid 를 절대 빼지 않는다(코딩규칙 7). 빼면 교차오답이 실제로 난다 — 9/15에 재현됨 | I141: ChromaDB 클라이언트 문법(collection.query)을 쓰지 않는다. 별도 벡터DB 서버는 도입하지 않는다 | J141: 숙소 A 질문에 숙소 B 청크가 섞이지 않는지 + 격리를 뺐을 때는 섞이는지 둘 다 확인(대조군)
A142: 2026-09-18(금) | B142: 3단계 | C142: 코드구현 | D142: 고객 응대 자동화 | E142: N3 임베딩 생성 + 지식베이스 적재 경로(POST /knowledge-chunks) | F142: 본인 — Claude Code(터미널 직접실행 권장) | G142: backend/app/api/v1/endpoints/rag.py | H142: 등록 시 임베딩을 동기 생성해 즉시 검색 가능한 상태로 돌려준다(api_contract 8절) — 상태 폴링을 만들지 않는다 | I142: 호스트 내부 재량(조기체크인 수용 여부 등)은 등록하지 않는다(코딩규칙 13). 공식 규정만 넣는다 | J142: 등록 직후 그 문장으로 검색해 1위로 나오는지 확인
A143: 2026-09-19(토) | B143: 3단계 | C143: 코드구현 | D143: 고객 응대 자동화 | E143: N4 pii_masking.py — Claude 전송 전 전화·이메일·여권·카드번호 마스킹 | F143: 본인 — Claude Code(터미널 직접실행 권장) | G143: backend/app/utils/pii_masking.py | H143: DB에는 원본을 그대로 저장한다 — 마스킹은 외부(Claude)로 나가는 텍스트에만 적용한다 | I143: 게스트가 본문에 직접 적어 보내는 경우를 잡는 것이 목적이다. DB에 연락처 컬럼이 없다는 것과 별개다 | J143: 전화·이메일·여권·카드번호가 든 문장을 넣어 네 가지가 전부 가려지는지 + guest_name이 프롬프트에 없는지 확인
A144: 2026-09-19(토) | B144: 3단계 | C144: 코드구현 | D144: 고객 응대 자동화 | E144: N5 agent_graph.py — Claude 단일 통합호출(structured outputs) | F144: 본인 — Claude Code(터미널 직접실행 권장) | G144: backend/app/services/ai/agent_graph.py | H144: 분류+위험도+다국어+근거를 1회 호출로 받는다. 절대 여러 LLM 노드로 쪼개지 않는다(비용 통제) | I144: content[0]이 text가 아닐 수 있다(9/15에 ThinkingBlock 간헐 확인). 프리필은 400이라 쓸 수 없다 — structured outputs를 쓴다 | J144: 같은 문의 2건으로 JSON 직파싱이 되는지 + 타임아웃(최초10초/재시도5초)이 실제로 발동하는지 확인
...

Sheet 일일 크로스체크
A1: 3rd Host AI — 일일 크로스체크 카드 (매일 아침 확인용)
A2: 사용법: 매일 아침 해당 날짜 카드를 열어 순서대로 진행 → 완료마다 '완료' 열에 체크 → 하단 '아침 크로스체크'에 확인 기록
A4: 📅 2026-08-31(월) · 1일차 · 작업 3건
A5: 🎯 오늘의 타이틀: Host-Property-Room-Bed 계층 스키마 확정(모두 optional)
A6: 순서 | B6: 세부 작업 | C6: 활용도구 | D6: 파일 위치 | E6: 핵심포인트 / 주의할 점 | F6: 확인방법 | G6: 완료
A7: 1 | B7: Host-Property-Room-Bed 계층 스키마 확정(모두 optional) | C7: Gemini(검토보조) | D7: docs/3rd_host_ai_db_spec_v1.md (2.1~2.4절) | E7: ▶ 독채(3룸통대여)와 호스텔(개별실판매)을 하나의 구조로 동시 표현하는 것이 핵심 차별화 ⚠ Room/Bed를 모두 optional로 둬야 함 — 강제로 NOT NULL 만들면 독채 예약 자체를 표현 못함 | F7: 3룸숙소=Property단위, 호스텔=Room단위 두 시나리오 모두 예약 생성이 가능한지 확인 | G7: ☑
A8: 2 | B8: STEP0: DB명세서v1(3rd_host_ai_db_spec_v1.md)을 스키마 최종권위 문서로 확정 + 구버전 ERD(guests/payments 등 포함 폐기 초안) 폐기처리 | C8: Claude(대화보조) | D8: docs/3rd_host_ai_db_spec_v1.md (전체) | E8: ▶ DB명세서에 이미 결정된 내용을 그대로 반영하는 단계 — 새로 고민하지 않는다 ⚠ 임의로 필드나 값을 추가하지 않는다(범위확장 방지 원칙) | F8: DB명세서 해당 섹션과 실제 반영내용을 나란히 놓고 비교 | G8: ☑
A9: 3 | B9: Property.accommodation_type 단일 ENUM 필드 확정 | C9: Gemini(검토보조) | D9: docs/3rd_host_ai_db_spec_v1.md (1. ENUM 타입 정의) | E9: ▶ 단일 ENUM(한 공간에 복수 숙박업 유형 등록은 법적으로 불가능하다고 확인됨) ⚠ 6개 값 정확히(URBAN_HOMESTAY,RURAL_HOMESTAY,HANOK,HOSTEL,LODGING_FACILITY,GENERAL_LODGING) — PENSION/OTHER/HANOK_STAY 같은 임의값 절대 금지 | F9: DB명세서 1절 ENUM 정의와 실제 반영값을 한 글자씩 diff 비교 | G9: ☑
A10: 🎬 오늘의 시나리오 | C10: [상황] 여러 문서(DB명세서/ERD/체크리스트)가 각각 따로 만들어지면 어느 게 진짜 기준인지 헷갈리기 쉬움 [동작] ① DB명세서v1을 스키마의 유일한 최종권위 문서(SSOT)로 확정 ② 기존에 떠돌던 구버전 ERD 초안은 전부 폐기 처리 ③ 이후 모든 문서가 이 명세서를 기준으로 동기화되도록 원칙 확립 [원칙 없었다면] 여러 버전의 스키마 문서가 동시에 존재하면, 오늘 하루 종일 겪은 것처럼 문서끼리 서로 다른 말을 하는 크로스체크 지옥이 반복됨
A11: 🌅 아침 크로스체크 | C11: ☑ 전날 순서대로 실행됨 ☑ 위 작업 전부 완료 ☑ git commit 완료 ☑ 전날 백업 실행(backup_push.ps1/.bat 더블클릭 → git push+Desktop 미러백업) | G11: 메모:
A13: 📅 2026-09-01(화) · 2일차 · 작업 9건
A14: 🎯 오늘의 타이틀: Reservation.bookable_unit_type(PROPERTY/ROOM/BED) 설계
A15: 순서 | B15: 세부 작업 | C15: 활용도구 | D15: 파일 위치 | E15: 핵심포인트 / 주의할 점 | F15: 확인방법 | G15: 완료
A16: 1 | B16: Reservation.bookable_unit_type(PROPERTY/ROOM/BED) 설계 | C16: Gemini(검토보조) | D16: docs/3rd_host_ai_db_spec_v1.md (2.2 PROPERTIES / 2.6 RESERVATIONS) | E16: ▶ PROPERTY/ROOM/BED 3종 판매단위를 하나의 Reservation 테이블로 표현 ⚠ 이 값과 room_id/bed_id 실사용 일치여부는 DB CHECK로 못 잡음(다른 테이블이라 PostgreSQL 일반 CHECK 불가) — 반드시 애플리케이션 검증 필요 | F16: bookable_unit_type=PROPERTY인데 room_id가 채워진 예약을 일부러 넣어보고 애플리케이션이 막는지 테스트 | G16: ☑
A17: 2 | B17: PROPERTY 단위 예약시 하위 Room 전체 블록 인터셉터 로직 정의(본인 3룸숙소 실제케이스) | C17: Gemini(검토보조) | D17: docs/3rd_host_ai_db_spec_v1.md (2.6.1 예약 겹침 방지) | E17: ▶ 본인 3룸숙소의 실제 운영형태(통대여)를 반영하는 핵심 로직 ⚠ EXCLUDE 제약만으로는 PROPERTY예약↔ROOM/BED예약 교차충돌을 못 막음 — 반드시 트랜잭션 검증 코드로 방어 | F17: 3룸 전체예약 확정 후 그 중 방 1개만 별도 예약 시도 → 반드시 차단되는지 확인 | G17: ☑
A18: 3 | B18: reservation_status / refund_status 분리 설계 | C18: Gemini(검토보조) | D18: docs/3rd_host_ai_db_spec_v1.md (2.6 RESERVATIONS 컬럼) | E18: ▶ '투숙완료(COMPLETED)'와 '부분환불(PARTIAL)'을 동시에 표현할 수 있어야 함 ⚠ 하나의 status 컬럼으로 합치면 이 조합 자체를 표현할 수 없음 | F18: COMPLETED+PARTIAL 조합을 실제로 저장해보고 정상 저장되는지 확인 | G18: ☑
A19: 4 | B19: Reservation CHECK 제약(bookable_unit_type↔room_id/bed_id 조합) 확정 | C19: Claude(대화보조) | D19: docs/3rd_host_ai_db_spec_v1.md (2.2 PROPERTIES / 2.6 RESERVATIONS) | E19: ▶ room_id/bed_id 조합의 '내부 형태'만 DB가 검증 가능 ⚠ PostgreSQL CHECK는 다른 테이블(PROPERTIES) 값을 볼 수 없음 — bookable_unit_type과의 교차일치는 앱 책임임을 반드시 인지 | F19: 유효하지 않은 조합(bed_id만 있고 room_id는 NULL 등) INSERT 시도 → DB가 거부하는지 | G19: ☑
A20: 5 | B20: ROOMS/BEDS 계층 복합FK+UNIQUE + Reservation↔Channel/Room/Bed 동일Property 보장(통합확정) | C20: Claude(대화보조) | D20: docs/3rd_host_ai_db_spec_v1.md (2.3 ROOMS / 2.4 BEDS / 2.6 RESERVATIONS (A)) | E20: ▶ 다른 숙소 소속 Room을 잘못 참조하는 데이터오염을 DB가 원천 차단 ⚠ UNIQUE(room_id,property_id)는 중복방지용이 아니라 복합FK 참조용 후보키 — room_name/bed_label UNIQUE가 실제 중복방지 역할 | F20: Property A 소속 room_id를 Property B의 예약에 넣어보고 FK 위반으로 거부되는지 확인 | G20: ☑
A21: 6 | B21: UNIQUE 복합제약 3종 확정(channel_connection_id+external_uid / property_id+target_month / property_id+channel) | C21: Gemini(검토보조) | D21: docs/3rd_host_ai_db_spec_v1.md (2.5 / 2.6 / 2.8절) | E21: ▶ 플랫폼별 예약UID/월별정산/채널연결 각각 중복 방지 ⚠ 채널당 연결 1개 제한은 이번 MVP 한정 — 향후 여러 리스팅 대응은 2차 과제 | F21: 같은 property+channel 조합을 2번 생성 시도했을 때 에러가 나는지 확인 | G21: ☑
A22: 7 | B22: INQUIRY_RESPONSES 1:N + is_latest 플래그 설계 확정 | C22: Gemini(검토보조) | D22: docs/3rd_host_ai_db_spec_v1.md (2.12 INQUIRY_RESPONSES) | E22: ▶ 재시도/재답변 이력을 보존하는 1:N + is_latest 구조 ⚠ 새 응답을 만들 때 기존 is_latest를 먼저 false로 바꾸는 걸 빠뜨리면 부분UNIQUE 인덱스 위반 에러 발생 | F22: 같은 문의에 응답 2번 생성 후 is_latest=true인 행이 정확히 1개인지 쿼리로 확인 | G22: ☑
A23: 8 | B23: FINANCIAL_CONFIGS→MONTHLY_SETTLEMENTS 관계 제거(스냅샷 분리) 확정 | C23: Gemini(검토보조) | D23: docs/3rd_host_ai_db_spec_v1.md (2.7 FINANCIAL_CONFIGS / 2.8 MONTHLY_SETTLEMENTS) | E23: ▶ 정산은 스냅샷 — 수수료율이 나중에 바뀌어도 과거 정산결과는 불변이어야 함 ⚠ FINANCIAL_CONFIGS와 직접 FK로 연결하면 안 됨. applied_commission_rate 컬럼에 계산 당시 값을 별도로 저장 | F23: 수수료율을 0.155→0.16으로 바꾼 뒤, 과거 정산행의 applied_commission_rate가 여전히 0.155인지 확인 | G23: ☑
A24: 9 | B24: 제출용 기획서 초안 작성(주제/선정이유/일정표/기술스택 — 기존 대화내용 취합) | C24: Gemini(검토보조) | D24: docs/project_plan_draft.md (신규생성) | E24: ▶ DB명세서에 이미 결정된 내용을 그대로 반영하는 단계 — 새로 고민하지 않는다 ⚠ 임의로 필드나 값을 추가하지 않는다(범위확장 방지 원칙) | F24: DB명세서 해당 섹션과 실제 반영내용을 나란히 놓고 비교 | G24: ☑
A25: 🎬 오늘의 시나리오 | C25: [상황] 같은 시스템에서 강남(통예약)과 홍대(방단위예약)를 동시 처리해야 함 [동작] ① bookable_unit_type을 PROPERTY/ROOM/BED 3종으로 확정 ② 예약 생성시 이 값에 따라 room_id/bed_id 필수여부가 자동 결정 [원칙 없었다면] 판매단위 구분이 없으면 강남 통예약 중 방 하나만 따로 예약받는 사고를 시스템이 못 막음
A26: 🌅 아침 크로스체크 | C26: ☑ 전날 순서대로 실행됨 ☑ 위 작업 전부 완료 ☑ git commit 완료 ☑ 전날 백업 실행(backup_push.ps1/.bat 더블클릭 → git push+Desktop 미러백업) | G26: 메모:
A28: 📅 2026-09-02(수) · 3일차 · 작업 12건
A29: 🎯 오늘의 타이틀: financial_status(ESTIMATED/CONFIRMED/MANUALLY_ADJUSTED) 필드 설계
A30: 순서 | B30: 세부 작업 | C30: 활용도구 | D30: 파일 위치 | E30: 핵심포인트 / 주의할 점 | F30: 확인방법 | G30: 완료
A31: 1 | B31: financial_status(ESTIMATED/CONFIRMED/MANUALLY_ADJUSTED) 필드 설계 | C31: Gemini(검토보조) | D31: docs/3rd_host_ai_db_spec_v1.md (2.6 RESERVATIONS 컬럼) | E31: ▶ DB명세서에 이미 결정된 내용을 그대로 반영하는 단계 — 새로 고민하지 않는다 ⚠ 임의로 필드나 값을 추가하지 않는다(범위확장 방지 원칙) | F31: DB명세서 해당 섹션과 실제 반영내용을 나란히 놓고 비교 | G31: ☑
A32: 2 | B32: 날짜 5종 분리 확정(booked_at/check_in/check_out/expected_settlement_at/actual_settlement_at) | C32: Gemini(검토보조) | D32: docs/3rd_host_ai_db_spec_v1.md (2.6 RESERVATIONS 컬럼) | E32: ▶ DB명세서에 이미 결정된 내용을 그대로 반영하는 단계 — 새로 고민하지 않는다 ⚠ 임의로 필드나 값을 추가하지 않는다(범위확장 방지 원칙) | F32: DB명세서 해당 섹션과 실제 반영내용을 나란히 놓고 비교 | G32: ☑
A33: 3 | B33: ChannelConnection 모델 설계(channel/external_property_id/sync_status/last_synced_at) | C33: Gemini(검토보조) | D33: docs/3rd_host_ai_db_spec_v1.md (2.6 RESERVATIONS 컬럼) | E33: ▶ DB명세서에 이미 결정된 내용을 그대로 반영하는 단계 — 새로 고민하지 않는다 ⚠ 임의로 필드나 값을 추가하지 않는다(범위확장 방지 원칙) | F33: DB명세서 해당 섹션과 실제 반영내용을 나란히 놓고 비교 | G33: ☑
A34: 4 | B34: ChecklistTemplate.renewal_trigger_type(NONE/EXPIRATION_BASED/EVENT_BASED) 필드 추가 | C34: Gemini(검토보조) | D34: docs/3rd_host_ai_db_spec_v1.md (2.16 CHECKLIST_ITEMS) | E34: ▶ DB명세서에 이미 결정된 내용을 그대로 반영하는 단계 — 새로 고민하지 않는다 ⚠ 임의로 필드나 값을 추가하지 않는다(범위확장 방지 원칙) | F34: DB명세서 해당 섹션과 실제 반영내용을 나란히 놓고 비교 | G34: ☑
A35: 5 | B35: Property 단위 데이터 격리 원칙 확정(KB/Reservation/Checklist/SmartLock 전체) | C35: Claude(대화보조) | D35: docs/3rd_host_ai_db_spec_v1.md (4.0절 DB보장/앱보장 구분) | E35: ▶ DB명세서에 이미 결정된 내용을 그대로 반영하는 단계 — 새로 고민하지 않는다 ⚠ 임의로 필드나 값을 추가하지 않는다(범위확장 방지 원칙) | F35: DB명세서 해당 섹션과 실제 반영내용을 나란히 놓고 비교 | G35: ☑
A36: 6 | B36: ACTION_ITEMS 중복생성 idempotency 정책 문서화(동일 reservation_id+category+OPEN 재사용) | C36: Gemini(검토보조) | D36: docs/3rd_host_ai_db_spec_v1.md (해당 섹션) | E36: ▶ DB명세서에 이미 결정된 내용을 그대로 반영하는 단계 — 새로 고민하지 않는다 ⚠ 임의로 필드나 값을 추가하지 않는다(범위확장 방지 원칙) | F36: DB명세서 해당 섹션과 실제 반영내용을 나란히 놓고 비교 | G36: ☑
A37: 7 | B37: risk_level '규칙기반 우선순위'로 문서화(법적판단 아님 명시) | C37: Gemini(검토보조) | D37: docs/3rd_host_ai_db_spec_v1.md (해당 섹션) | E37: ▶ DB명세서에 이미 결정된 내용을 그대로 반영하는 단계 — 새로 고민하지 않는다 ⚠ 임의로 필드나 값을 추가하지 않는다(범위확장 방지 원칙) | F37: DB명세서 해당 섹션과 실제 반영내용을 나란히 놓고 비교 | G37: ☑
A38: 8 | B38: 인덱스 요구사항 목록화(property_id 계열 전체+ActionCenter 복합인덱스, 실제생성은 9/5) | C38: Gemini(검토보조) | D38: docs/3rd_host_ai_db_spec_v1.md (해당 섹션) | E38: ▶ DB명세서에 이미 결정된 내용을 그대로 반영하는 단계 — 새로 고민하지 않는다 ⚠ 임의로 필드나 값을 추가하지 않는다(범위확장 방지 원칙) | F38: DB명세서 해당 섹션과 실제 반영내용을 나란히 놓고 비교 | G38: ☑
A39: 9 | B39: DB명세서↔ERD↔체크리스트 3문서 최종 동기화 확인 | C39: Claude(대화보조) | D39: docs/erd.md 또는 mermaid 다이어그램(신규) | E39: ▶ DB명세서에 이미 결정된 내용을 그대로 반영하는 단계 — 새로 고민하지 않는다 ⚠ 임의로 필드나 값을 추가하지 않는다(범위확장 방지 원칙) | F39: DB명세서 해당 섹션과 실제 반영내용을 나란히 놓고 비교 | G39: ☑
A40: 10 | B40: 기획서 최종 검토 및 다듬기 | C40: Claude(대화보조) | D40: docs/project_plan_draft.md (신규생성) | E40: ▶ DB명세서에 이미 결정된 내용을 그대로 반영하는 단계 — 새로 고민하지 않는다 ⚠ 임의로 필드나 값을 추가하지 않는다(범위확장 방지 원칙) | F40: DB명세서 해당 섹션과 실제 반영내용을 나란히 놓고 비교 | G40: ☑
A41: 11 | B41: Azure Cloud 서비스 확인 완료 → Render로 최종 확정(Azure 전환 안함) | C41: Claude(대화보조) | D41: 클라우드 콘솔(파일 아님) — Azure Portal / Google AI Studio | E41: ▶ DB명세서에 이미 결정된 내용을 그대로 반영하는 단계 — 새로 고민하지 않는다 ⚠ 임의로 필드나 값을 추가하지 않는다(범위확장 방지 원칙) | F41: DB명세서 해당 섹션과 실제 반영내용을 나란히 놓고 비교 | G41: ☑
A42: 12 | B42: Google AI Studio 무료 Gemini API키 미리 발급(백업용, 5분 소요, 스택변경 아님) | C42: Claude(대화보조) | D42: 클라우드 콘솔(파일 아님) — Azure Portal / Google AI Studio | E42: ▶ DB명세서에 이미 결정된 내용을 그대로 반영하는 단계 — 새로 고민하지 않는다 ⚠ 임의로 필드나 값을 추가하지 않는다(범위확장 방지 원칙) | F42: DB명세서 해당 섹션과 실제 반영내용을 나란히 놓고 비교 | G42: ☑
A43: 🎬 오늘의 시나리오 | C43: [상황] 정산 화면에 표시되는 금액이 확정된 건지 추정치인지 게스트/호스트 둘 다 헷갈리기 쉬움 [동작] ① financial_status를 ESTIMATED/CONFIRMED/MANUALLY_ADJUSTED 3종으로 분리 ② 화면에 상태별 뱃지로 명확히 구분 표시 [원칙 없었다면] 상태 구분 없이 숫자만 보여주면, 아직 확정 안 된 예상금액을 실수령액으로 착각하는 사고 발생
...
